<?xml version="1.0" ?>
<robot name="quadru">

<material name="silver">
  <color rgba="0.700 0.700 0.700 1.000"/>
</material>

<material name="orange">
  <color rgba="1.000 0.647 0.000 1.000"/>
</material>

<material name="black">
  <color rgba="0.000 0.000 0.000 1.000"/>
</material>

<material name="red">
  <color rgba="1.000 0.000 0.000 1.000"/>
</material>

<material name="blue">
  <color rgba="0.000 0.000 1.000 1.000"/>
</material>

<material name="green">
  <color rgba="0.000 1.000 0.000 1.000"/>
</material>

<link name="base_link">
  <inertial>
    <origin xyz="-0.03309983762405305 0.028399999999999155 0.00224168443202275" rpy="0 0 0"/>
    <mass value="0.25033538405498423"/>
    <inertia ixx="0.0005969563697551504" iyy="0.0003006572635330181" izz="0.0008736394773121216" ixy="-2.6008166974234026e-14" iyz="-1.7211709488207383e-18" ixz="2.005288946034517e-08"/>
  </inertial>
  <visual>
    <origin xyz="0 0 0" rpy="0 0 0"/>
    <geometry>
      <mesh filename="meshes/base_link.stl" scale="0.001 0.001 0.001"/>
    </geometry>
    <material name="silver"/>
    <material/>
  </visual>
  <collision>
    <origin xyz="0 0 0" rpy="0 0 0"/>
    <geometry>
      <mesh filename="meshes/base_link.stl" scale="0.001 0.001 0.001"/>
    </geometry>
  </collision>
</link>

<link name="fl_shoulder1">
  <inertial>
    <origin xyz="0.02038476147009273 -0.01614910531145121 0.007593460755879494" rpy="0 0 0"/>
    <mass value="0.08997986177136631"/>
    <inertia ixx="3.8315761135564327e-05" iyy="0.00011132815270649087" izz="8.856025914479303e-05" ixy="-2.735120460415426e-07" iyz="-1.0188214422829513e-07" ixz="-2.3542560848743403e-05"/>
  </inertial>
  <visual>
    <origin xyz="-0.0105 0.0406 1e-06" rpy="0 0 0"/>
    <geometry>
      <mesh filename="meshes/fl_shoulder1.stl" scale="0.001 0.001 0.001"/>
    </geometry>
    <material name="red"/>
    <material/>
  </visual>
  <collision>
    <origin xyz="-0.0105 0.0406 1e-06" rpy="0 0 0"/>
    <geometry>
      <mesh filename="meshes/fl_shoulder1.stl" scale="0.001 0.001 0.001"/>
    </geometry>
  </collision>
</link>

<link name="fl_upper1">
  <inertial>
    <origin xyz="0.02874213224775385 -0.04705657486243686 0.003941150192365954" rpy="0 0 0"/>
    <mass value="0.06768345771416033"/>
    <inertia ixx="8.3471278698269e-05" iyy="4.829786585998309e-05" izz="0.00011474259337516642" ixy="-2.467345610746431e-06" iyz="-2.7957197225755127e-06" ixz="-1.456135694693269e-08"/>
  </inertial>
  <visual>
    <origin xyz="-0.038201 0.0566 -0.010497" rpy="0 0 0"/>
    <geometry>
      <mesh filename="meshes/fl_upper1.stl" scale="0.001 0.001 0.001"/>
    </geometry>
    <material name="green"/>
    <material/>
  </visual>
  <collision>
    <origin xyz="-0.038201 0.0566 -0.010497" rpy="0 0 0"/>
    <geometry>
      <mesh filename="meshes/fl_upper1.stl" scale="0.001 0.001 0.001"/>
    </geometry>
  </collision>
</link>

<link name="fl_lower1">
  <inertial>
    <origin xyz="-0.025886007718800827 0.03867162068964147 0.000721706340641318" rpy="0 0 0"/>
    <mass value="0.08196109414977758"/>
    <inertia ixx="0.00013807875504800071" iyy="1.6992356631682698e-05" izz="0.0001478076856311454" ixy="7.7338121520212e-06" iyz="1.6899029346605836e-06" ixz="1.8885867080679995e-07"/>
  </inertial>
  <visual>
    <origin xyz="-0.089801 0.1566 -0.010493" rpy="0 0 0"/>
    <geometry>
      <mesh filename="meshes/fl_lower1.stl" scale="0.001 0.001 0.001"/>
    </geometry>
    <material name="blue"/>
    <material/>
  </visual>
  <collision>
    <origin xyz="-0.089801 0.1566 -0.010493" rpy="0 0 0"/>
    <geometry>
      <mesh filename="meshes/fl_lower1.stl" scale="0.001 0.001 0.001"/>
    </geometry>
  </collision>
</link>

<link name="bl_shoulder1">
  <inertial>
    <origin xyz="0.02038476147001647 0.01614910531145096 0.007593460755879429" rpy="0 0 0"/>
    <mass value="0.08997986177136663"/>
    <inertia ixx="3.831576113061592e-05" iyy="0.0001113281527090578" izz="8.85602591523104e-05" ixy="2.7351204604029577e-07" iyz="1.0188214422823414e-07" ixz="-2.3542560848795763e-05"/>
  </inertial>
  <visual>
    <origin xyz="-0.0105 -0.0974 1e-06" rpy="0 0 0"/>
    <geometry>
      <mesh filename="meshes/bl_shoulder1.stl" scale="0.001 0.001 0.001"/>
    </geometry>
    <material name="red"/>
    <material/>
  </visual>
  <collision>
    <origin xyz="-0.0105 -0.0974 1e-06" rpy="0 0 0"/>
    <geometry>
      <mesh filename="meshes/bl_shoulder1.stl" scale="0.001 0.001 0.001"/>
    </geometry>
  </collision>
</link>

<link name="bl_upper1">
  <inertial>
    <origin xyz="0.028742132246898977 0.047056574862436557 0.0039411501923660285" rpy="0 0 0"/>
    <mass value="0.0676834577141605"/>
    <inertia ixx="8.347127869827117e-05" iyy="4.829786585997675e-05" izz="0.00011474259337516252" ixy="2.4673456098951154e-06" iyz="2.795719722575418e-06" ixz="-1.4561357122017788e-08"/>
  </inertial>
  <visual>
    <origin xyz="-0.038201 -0.1134 -0.010497" rpy="0 0 0"/>
    <geometry>
      <mesh filename="meshes/bl_upper1.stl" scale="0.001 0.001 0.001"/>
    </geometry>
    <material name="green"/>
    <material/>
  </visual>
  <collision>
    <origin xyz="-0.038201 -0.1134 -0.010497" rpy="0 0 0"/>
    <geometry>
      <mesh filename="meshes/bl_upper1.stl" scale="0.001 0.001 0.001"/>
    </geometry>
  </collision>
</link>

<link name="bl_lower1">
  <inertial>
    <origin xyz="-0.025886008980240238 -0.038671625747005944 0.0007217062814401584" rpy="0 0 0"/>
    <mass value="0.08196110090858688"/>
    <inertia ixx="0.00013807878114503519" iyy="1.6992358552698778e-05" izz="0.00014780771296968916" ixy="-7.733818492697449e-06" iyz="-1.6899032322383826e-06" ixz="1.8885859658792996e-07"/>
  </inertial>
  <visual>
    <origin xyz="-0.089801 -0.2134 -0.010493" rpy="0 0 0"/>
    <geometry>
      <mesh filename="meshes/bl_lower1.stl" scale="0.001 0.001 0.001"/>
    </geometry>
    <material name="blue"/>
    <material/>
  </visual>
  <collision>
    <origin xyz="-0.089801 -0.2134 -0.010493" rpy="0 0 0"/>
    <geometry>
      <mesh filename="meshes/bl_lower1.stl" scale="0.001 0.001 0.001"/>
    </geometry>
  </collision>
</link>

<link name="br_shoulder1">
  <inertial>
    <origin xyz="-0.020383660428958478 0.016149105311450973 0.007595735398294116" rpy="0 0 0"/>
    <mass value="0.08997986177136666"/>
    <inertia ixx="3.83225872710195e-05" iyy="0.00011132815270905824" izz="8.855343301190834e-05" ixy="-2.734972751410568e-07" iyz="1.0192178928894664e-07" ixz="2.3549842902258246e-05"/>
  </inertial>
  <visual>
    <origin xyz="0.0767 -0.0974 -6e-06" rpy="0 0 0"/>
    <geometry>
      <mesh filename="meshes/br_shoulder1.stl" scale="0.001 0.001 0.001"/>
    </geometry>
    <material name="red"/>
    <material/>
  </visual>
  <collision>
    <origin xyz="0.0767 -0.0974 -6e-06" rpy="0 0 0"/>
    <geometry>
      <mesh filename="meshes/br_shoulder1.stl" scale="0.001 0.001 0.001"/>
    </geometry>
  </collision>
</link>

<link name="br_upper1">
  <inertial>
    <origin xyz="-0.028742038524303334 0.047056574856869426 0.003944651495702471" rpy="0 0 0"/>
    <mass value="0.0676834577298832"/>
    <inertia ixx="8.347128358889076e-05" iyy="4.82978658668011e-05" izz="0.00011474258851024632" ixy="-2.466940328708792e-06" iyz="2.7960773380339855e-06" ixz="1.909419984673583e-08"/>
  </inertial>
  <visual>
    <origin xyz="0.104399 -0.1134 -0.010508" rpy="0 0 0"/>
    <geometry>
      <mesh filename="meshes/br_upper1.stl" scale="0.001 0.001 0.001"/>
    </geometry>
    <material name="green"/>
    <material/>
  </visual>
  <collision>
    <origin xyz="0.104399 -0.1134 -0.010508" rpy="0 0 0"/>
    <geometry>
      <mesh filename="meshes/br_upper1.stl" scale="0.001 0.001 0.001"/>
    </geometry>
  </collision>
</link>

<link name="br_lower1">
  <inertial>
    <origin xyz="0.025885634164955262 -0.03867162072338243 0.0007177687503543036" rpy="0 0 0"/>
    <mass value="0.0819610940704458"/>
    <inertia ixx="0.00013807870051668744" iyy="1.699235661872865e-05" izz="0.00014780774018649436" ixy="7.733567127382818e-06" iyz="-1.6910239787792838e-06" ixz="-1.8744842955689147e-07"/>
  </inertial>
  <visual>
    <origin xyz="0.155999 -0.2134 -0.010511" rpy="0 0 0"/>
    <geometry>
      <mesh filename="meshes/br_lower1.stl" scale="0.001 0.001 0.001"/>
    </geometry>
    <material name="blue"/>
    <material/>
  </visual>
  <collision>
    <origin xyz="0.155999 -0.2134 -0.010511" rpy="0 0 0"/>
    <geometry>
      <mesh filename="meshes/br_lower1.stl" scale="0.001 0.001 0.001"/>
    </geometry>
  </collision>
</link>

<link name="fr_shoulder1">
  <inertial>
    <origin xyz="-0.020383660429034736 -0.016149105311451188 0.007595735398294163" rpy="0 0 0"/>
    <mass value="0.08997986177136641"/>
    <inertia ixx="3.8322587275967524e-05" iyy="0.00011132815270649085" izz="8.855343300438983e-05" ixy="2.7349727514289993e-07" iyz="-1.0192178928889243e-07" ixz="2.3549842902204605e-05"/>
  </inertial>
  <visual>
    <origin xyz="0.0767 0.0406 -6e-06" rpy="0 0 0"/>
    <geometry>
      <mesh filename="meshes/fr_shoulder1.stl" scale="0.001 0.001 0.001"/>
    </geometry>
    <material name="red"/>
    <material/>
  </visual>
  <collision>
    <origin xyz="0.0767 0.0406 -6e-06" rpy="0 0 0"/>
    <geometry>
      <mesh filename="meshes/fr_shoulder1.stl" scale="0.001 0.001 0.001"/>
    </geometry>
  </collision>
</link>

<link name="fr_upper1">
  <inertial>
    <origin xyz="-0.02874203852344863 -0.047056574856869635 0.003944651495702398" rpy="0 0 0"/>
    <mass value="0.06768345772988303"/>
    <inertia ixx="8.347128358889076e-05" iyy="4.8297865866795244e-05" izz="0.00011474258851023982" ixy="2.466940327858669e-06" iyz="-2.796077338033823e-06" ixz="1.909420002172606e-08"/>
  </inertial>
  <visual>
    <origin xyz="0.104399 0.0566 -0.010508" rpy="0 0 0"/>
    <geometry>
      <mesh filename="meshes/fr_upper1.stl" scale="0.001 0.001 0.001"/>
    </geometry>
    <material name="green"/>
    <material/>
  </visual>
  <collision>
    <origin xyz="0.104399 0.0566 -0.010508" rpy="0 0 0"/>
    <geometry>
      <mesh filename="meshes/fr_upper1.stl" scale="0.001 0.001 0.001"/>
    </geometry>
  </collision>
</link>

<link name="fr_lower1">
  <inertial>
    <origin xyz="0.02588563542684455 0.038671625781964564 0.0007177686909025528" rpy="0 0 0"/>
    <mass value="0.08196110083089318"/>
    <inertia ixx="0.00013807872662013388" iyy="1.6992358540615562e-05" izz="0.00014780776753207893" ixy="-7.733573470322013e-06" iyz="1.6910242776153265e-06" ixz="-1.8744835500579483e-07"/>
  </inertial>
  <visual>
    <origin xyz="0.155999 0.1566 -0.010511" rpy="0 0 0"/>
    <geometry>
      <mesh filename="meshes/fr_lower1.stl" scale="0.001 0.001 0.001"/>
    </geometry>
    <material name="blue"/>
    <material/>
  </visual>
  <collision>
    <origin xyz="0.155999 0.1566 -0.010511" rpy="0 0 0"/>
    <geometry>
      <mesh filename="meshes/fr_lower1.stl" scale="0.001 0.001 0.001"/>
    </geometry>
  </collision>
</link>

<joint name="fl1" type="continuous">
  <origin xyz="0.0105 -0.0406 -1e-06" rpy="0 0 0"/>
  <parent link="base_link"/>
  <child link="fl_shoulder1"/>
  <axis xyz="-0.0 -1.0 -0.0"/>
</joint>
<transmission name="fl1_tran">
  <type>transmission_interface/SimpleTransmission</type>
  <joint name="fl1">
    <hardwareInterface>PositionJointInterface</hardwareInterface>
  </joint>
  <actuator name="fl1_actr">
    <hardwareInterface>PositionJointInterface</hardwareInterface>
    <mechanicalReduction>1</mechanicalReduction>
  </actuator>
</transmission>

<joint name="fl2" type="continuous">
  <origin xyz="0.027701 -0.016 0.010498" rpy="0 0 0"/>
  <parent link="fl_shoulder1"/>
  <child link="fl_upper1"/>
  <axis xyz="1.0 -0.0 -7.2e-05"/>
</joint>
<transmission name="fl2_tran">
  <type>transmission_interface/SimpleTransmission</type>
  <joint name="fl2">
    <hardwareInterface>PositionJointInterface</hardwareInterface>
  </joint>
  <actuator name="fl2_actr">
    <hardwareInterface>PositionJointInterface</hardwareInterface>
    <mechanicalReduction>1</mechanicalReduction>
  </actuator>
</transmission>

<joint name="fl3" type="continuous">
  <origin xyz="0.0516 -0.1 -4e-06" rpy="0 0 0"/>
  <parent link="fl_upper1"/>
  <child link="fl_lower1"/>
  <axis xyz="-1.0 0.0 7.2e-05"/>
</joint>
<transmission name="fl3_tran">
  <type>transmission_interface/SimpleTransmission</type>
  <joint name="fl3">
    <hardwareInterface>PositionJointInterface</hardwareInterface>
  </joint>
  <actuator name="fl3_actr">
    <hardwareInterface>PositionJointInterface</hardwareInterface>
    <mechanicalReduction>1</mechanicalReduction>
  </actuator>
</transmission>

<joint name="bl1" type="continuous">
  <origin xyz="0.0105 0.0974 -1e-06" rpy="0 0 0"/>
  <parent link="base_link"/>
  <child link="bl_shoulder1"/>
  <axis xyz="0.0 1.0 0.0"/>
</joint>
<transmission name="bl1_tran">
  <type>transmission_interface/SimpleTransmission</type>
  <joint name="bl1">
    <hardwareInterface>PositionJointInterface</hardwareInterface>
  </joint>
  <actuator name="bl1_actr">
    <hardwareInterface>PositionJointInterface</hardwareInterface>
    <mechanicalReduction>1</mechanicalReduction>
  </actuator>
</transmission>

<joint name="bl2" type="continuous">
  <origin xyz="0.027701 0.016 0.010498" rpy="0 0 0"/>
  <parent link="bl_shoulder1"/>
  <child link="bl_upper1"/>
  <axis xyz="1.0 -0.0 -7.2e-05"/>
</joint>
<transmission name="bl2_tran">
  <type>transmission_interface/SimpleTransmission</type>
  <joint name="bl2">
    <hardwareInterface>PositionJointInterface</hardwareInterface>
  </joint>
  <actuator name="bl2_actr">
    <hardwareInterface>PositionJointInterface</hardwareInterface>
    <mechanicalReduction>1</mechanicalReduction>
  </actuator>
</transmission>

<joint name="bl3" type="continuous">
  <origin xyz="0.0516 0.1 -4e-06" rpy="0 0 0"/>
  <parent link="bl_upper1"/>
  <child link="bl_lower1"/>
  <axis xyz="-1.0 -0.0 7.2e-05"/>
</joint>
<transmission name="bl3_tran">
  <type>transmission_interface/SimpleTransmission</type>
  <joint name="bl3">
    <hardwareInterface>PositionJointInterface</hardwareInterface>
  </joint>
  <actuator name="bl3_actr">
    <hardwareInterface>PositionJointInterface</hardwareInterface>
    <mechanicalReduction>1</mechanicalReduction>
  </actuator>
</transmission>

<joint name="br1" type="continuous">
  <origin xyz="-0.0767 0.0974 6e-06" rpy="0 0 0"/>
  <parent link="base_link"/>
  <child link="br_shoulder1"/>
  <axis xyz="0.0 1.0 0.0"/>
</joint>
<transmission name="br1_tran">
  <type>transmission_interface/SimpleTransmission</type>
  <joint name="br1">
    <hardwareInterface>PositionJointInterface</hardwareInterface>
  </joint>
  <actuator name="br1_actr">
    <hardwareInterface>PositionJointInterface</hardwareInterface>
    <mechanicalReduction>1</mechanicalReduction>
  </actuator>
</transmission>

<joint name="br2" type="continuous">
  <origin xyz="-0.027699 0.016 0.010502" rpy="0 0 0"/>
  <parent link="br_shoulder1"/>
  <child link="br_upper1"/>
  <axis xyz="-1.0 0.0 7.2e-05"/>
</joint>
<transmission name="br2_tran">
  <type>transmission_interface/SimpleTransmission</type>
  <joint name="br2">
    <hardwareInterface>PositionJointInterface</hardwareInterface>
  </joint>
  <actuator name="br2_actr">
    <hardwareInterface>PositionJointInterface</hardwareInterface>
    <mechanicalReduction>1</mechanicalReduction>
  </actuator>
</transmission>

<joint name="br3" type="continuous">
  <origin xyz="-0.0516 0.1 3e-06" rpy="0 0 0"/>
  <parent link="br_upper1"/>
  <child link="br_lower1"/>
  <axis xyz="1.0 -0.0 -7.2e-05"/>
</joint>
<transmission name="br3_tran">
  <type>transmission_interface/SimpleTransmission</type>
  <joint name="br3">
    <hardwareInterface>PositionJointInterface</hardwareInterface>
  </joint>
  <actuator name="br3_actr">
    <hardwareInterface>PositionJointInterface</hardwareInterface>
    <mechanicalReduction>1</mechanicalReduction>
  </actuator>
</transmission>

<joint name="fr1" type="continuous">
  <origin xyz="-0.0767 -0.0406 6e-06" rpy="0 0 0"/>
  <parent link="base_link"/>
  <child link="fr_shoulder1"/>
  <axis xyz="-0.0 -1.0 -0.0"/>
</joint>
<transmission name="fr1_tran">
  <type>transmission_interface/SimpleTransmission</type>
  <joint name="fr1">
    <hardwareInterface>PositionJointInterface</hardwareInterface>
  </joint>
  <actuator name="fr1_actr">
    <hardwareInterface>PositionJointInterface</hardwareInterface>
    <mechanicalReduction>1</mechanicalReduction>
  </actuator>
</transmission>

<joint name="fr2" type="continuous">
  <origin xyz="-0.027699 -0.016 0.010502" rpy="0 0 0"/>
  <parent link="fr_shoulder1"/>
  <child link="fr_upper1"/>
  <axis xyz="-1.0 0.0 7.2e-05"/>
</joint>
<transmission name="fr2_tran">
  <type>transmission_interface/SimpleTransmission</type>
  <joint name="fr2">
    <hardwareInterface>PositionJointInterface</hardwareInterface>
  </joint>
  <actuator name="fr2_actr">
    <hardwareInterface>PositionJointInterface</hardwareInterface>
    <mechanicalReduction>1</mechanicalReduction>
  </actuator>
</transmission>

<joint name="fr3" type="continuous">
  <origin xyz="-0.0516 -0.1 3e-06" rpy="0 0 0"/>
  <parent link="fr_upper1"/>
  <child link="fr_lower1"/>
  <axis xyz="1.0 0.0 -7.2e-05"/>
</joint>
<transmission name="fr3_tran">
  <type>transmission_interface/SimpleTransmission</type>
  <joint name="fr3">
    <hardwareInterface>PositionJointInterface</hardwareInterface>
  </joint>
  <actuator name="fr3_actr">
    <hardwareInterface>PositionJointInterface</hardwareInterface>
    <mechanicalReduction>1</mechanicalReduction>
  </actuator>
</transmission>

</robot>
