<?xml version="1.0" ?>
<robot name="quadru" xmlns:xacro="http://www.ros.org/wiki/xacro">

<xacro:include filename="$(find quadru_description)/urdf/materials.xacro" />
<xacro:include filename="$(find quadru_description)/urdf/quadru.trans" />
<xacro:include filename="$(find quadru_description)/urdf/quadru.gazebo" />
<link name="base_link">
  <inertial>
    <origin xyz="-0.033099837624053066 0.028399999999999124 0.0022416844320227464" rpy="0 0 0"/>
    <mass value="0.2503353840549843"/>
    <inertia ixx="0.000597" iyy="0.000301" izz="0.000874" ixy="-0.0" iyz="-0.0" ixz="0.0"/>
  </inertial>
  <visual>
    <origin xyz="0 0 0" rpy="0 0 0"/>
    <geometry>
      <mesh filename="package://quadru_description/meshes/base_link.stl" scale="0.001 0.001 0.001"/>
    </geometry>
    <material name="silver"/>
  </visual>
  <collision>
    <origin xyz="0 0 0" rpy="0 0 0"/>
    <geometry>
      <mesh filename="package://quadru_description/meshes/base_link.stl" scale="0.001 0.001 0.001"/>
    </geometry>
  </collision>
</link>

<link name="fl_shoulder_1">
  <inertial>
    <origin xyz="0.02038476147009273 -0.01614910531145121 0.007593460755879494" rpy="0 0 0"/>
    <mass value="0.08997986177136631"/>
    <inertia ixx="3.8e-05" iyy="0.000111" izz="8.9e-05" ixy="-0.0" iyz="-0.0" ixz="-2.4e-05"/>
  </inertial>
  <visual>
    <origin xyz="-0.0105 0.0406 1e-06" rpy="0 0 0"/>
    <geometry>
      <mesh filename="package://quadru_description/meshes/fl_shoulder_1.stl" scale="0.001 0.001 0.001"/>
    </geometry>
    <material name="silver"/>
  </visual>
  <collision>
    <origin xyz="-0.0105 0.0406 1e-06" rpy="0 0 0"/>
    <geometry>
      <mesh filename="package://quadru_description/meshes/fl_shoulder_1.stl" scale="0.001 0.001 0.001"/>
    </geometry>
  </collision>
</link>

<link name="fl_upper_1">
  <inertial>
    <origin xyz="0.02874213224775385 -0.04705657486243686 0.003941150192365954" rpy="0 0 0"/>
    <mass value="0.06768345771416033"/>
    <inertia ixx="8.3e-05" iyy="4.8e-05" izz="0.000115" ixy="-2e-06" iyz="-3e-06" ixz="-0.0"/>
  </inertial>
  <visual>
    <origin xyz="-0.038201 0.0566 -0.010497" rpy="0 0 0"/>
    <geometry>
      <mesh filename="package://quadru_description/meshes/fl_upper_1.stl" scale="0.001 0.001 0.001"/>
    </geometry>
    <material name="silver"/>
  </visual>
  <collision>
    <origin xyz="-0.038201 0.0566 -0.010497" rpy="0 0 0"/>
    <geometry>
      <mesh filename="package://quadru_description/meshes/fl_upper_1.stl" scale="0.001 0.001 0.001"/>
    </geometry>
  </collision>
</link>

<link name="fl_lower_1">
  <inertial>
    <origin xyz="-0.02588600771880084 0.03867162068964146 0.000721706340641318" rpy="0 0 0"/>
    <mass value="0.08196109414977759"/>
    <inertia ixx="0.000138" iyy="1.7e-05" izz="0.000148" ixy="8e-06" iyz="2e-06" ixz="0.0"/>
  </inertial>
  <visual>
    <origin xyz="-0.089801 0.1566 -0.010493" rpy="0 0 0"/>
    <geometry>
      <mesh filename="package://quadru_description/meshes/fl_lower_1.stl" scale="0.001 0.001 0.001"/>
    </geometry>
    <material name="silver"/>
  </visual>
  <collision>
    <origin xyz="-0.089801 0.1566 -0.010493" rpy="0 0 0"/>
    <geometry>
      <mesh filename="package://quadru_description/meshes/fl_lower_1.stl" scale="0.001 0.001 0.001"/>
    </geometry>
  </collision>
</link>

<link name="bl_shoulder_1">
  <inertial>
    <origin xyz="0.02038476147001647 0.01614910531145096 0.007593460755879429" rpy="0 0 0"/>
    <mass value="0.08997986177136663"/>
    <inertia ixx="3.8e-05" iyy="0.000111" izz="8.9e-05" ixy="0.0" iyz="0.0" ixz="-2.4e-05"/>
  </inertial>
  <visual>
    <origin xyz="-0.0105 -0.0974 1e-06" rpy="0 0 0"/>
    <geometry>
      <mesh filename="package://quadru_description/meshes/bl_shoulder_1.stl" scale="0.001 0.001 0.001"/>
    </geometry>
    <material name="silver"/>
  </visual>
  <collision>
    <origin xyz="-0.0105 -0.0974 1e-06" rpy="0 0 0"/>
    <geometry>
      <mesh filename="package://quadru_description/meshes/bl_shoulder_1.stl" scale="0.001 0.001 0.001"/>
    </geometry>
  </collision>
</link>

<link name="bl_upper_1">
  <inertial>
    <origin xyz="0.028742132246898977 0.047056574862436557 0.0039411501923660285" rpy="0 0 0"/>
    <mass value="0.0676834577141605"/>
    <inertia ixx="8.3e-05" iyy="4.8e-05" izz="0.000115" ixy="2e-06" iyz="3e-06" ixz="-0.0"/>
  </inertial>
  <visual>
    <origin xyz="-0.038201 -0.1134 -0.010497" rpy="0 0 0"/>
    <geometry>
      <mesh filename="package://quadru_description/meshes/bl_upper_1.stl" scale="0.001 0.001 0.001"/>
    </geometry>
    <material name="silver"/>
  </visual>
  <collision>
    <origin xyz="-0.038201 -0.1134 -0.010497" rpy="0 0 0"/>
    <geometry>
      <mesh filename="package://quadru_description/meshes/bl_upper_1.stl" scale="0.001 0.001 0.001"/>
    </geometry>
  </collision>
</link>

<link name="br_shoulder_1">
  <inertial>
    <origin xyz="-0.020383660428958478 0.016149105311450973 0.007595735398294116" rpy="0 0 0"/>
    <mass value="0.08997986177136666"/>
    <inertia ixx="3.8e-05" iyy="0.000111" izz="8.9e-05" ixy="-0.0" iyz="0.0" ixz="2.4e-05"/>
  </inertial>
  <visual>
    <origin xyz="0.0767 -0.0974 -6e-06" rpy="0 0 0"/>
    <geometry>
      <mesh filename="package://quadru_description/meshes/br_shoulder_1.stl" scale="0.001 0.001 0.001"/>
    </geometry>
    <material name="silver"/>
  </visual>
  <collision>
    <origin xyz="0.0767 -0.0974 -6e-06" rpy="0 0 0"/>
    <geometry>
      <mesh filename="package://quadru_description/meshes/br_shoulder_1.stl" scale="0.001 0.001 0.001"/>
    </geometry>
  </collision>
</link>

<link name="br_upper_1">
  <inertial>
    <origin xyz="-0.028742038524303307 0.04705657485686937 0.003944651495702469" rpy="0 0 0"/>
    <mass value="0.06768345772988323"/>
    <inertia ixx="8.3e-05" iyy="4.8e-05" izz="0.000115" ixy="-2e-06" iyz="3e-06" ixz="0.0"/>
  </inertial>
  <visual>
    <origin xyz="0.104399 -0.1134 -0.010508" rpy="0 0 0"/>
    <geometry>
      <mesh filename="package://quadru_description/meshes/br_upper_1.stl" scale="0.001 0.001 0.001"/>
    </geometry>
    <material name="silver"/>
  </visual>
  <collision>
    <origin xyz="0.104399 -0.1134 -0.010508" rpy="0 0 0"/>
    <geometry>
      <mesh filename="package://quadru_description/meshes/br_upper_1.stl" scale="0.001 0.001 0.001"/>
    </geometry>
  </collision>
</link>

<link name="br_lower_1">
  <inertial>
    <origin xyz="0.025885634164955262 -0.038671620723382455 0.0007177687503543053" rpy="0 0 0"/>
    <mass value="0.08196109407044583"/>
    <inertia ixx="0.000138" iyy="1.7e-05" izz="0.000148" ixy="8e-06" iyz="-2e-06" ixz="-0.0"/>
  </inertial>
  <visual>
    <origin xyz="0.155999 -0.2134 -0.010511" rpy="0 0 0"/>
    <geometry>
      <mesh filename="package://quadru_description/meshes/br_lower_1.stl" scale="0.001 0.001 0.001"/>
    </geometry>
    <material name="silver"/>
  </visual>
  <collision>
    <origin xyz="0.155999 -0.2134 -0.010511" rpy="0 0 0"/>
    <geometry>
      <mesh filename="package://quadru_description/meshes/br_lower_1.stl" scale="0.001 0.001 0.001"/>
    </geometry>
  </collision>
</link>

<link name="bl_lower_1">
  <inertial>
    <origin xyz="-0.025886008980240224 -0.03867162574700592 0.0007217062814401584" rpy="0 0 0"/>
    <mass value="0.08196110090858688"/>
    <inertia ixx="0.000138" iyy="1.7e-05" izz="0.000148" ixy="-8e-06" iyz="-2e-06" ixz="0.0"/>
  </inertial>
  <visual>
    <origin xyz="-0.089801 -0.2134 -0.010493" rpy="0 0 0"/>
    <geometry>
      <mesh filename="package://quadru_description/meshes/bl_lower_1.stl" scale="0.001 0.001 0.001"/>
    </geometry>
    <material name="silver"/>
  </visual>
  <collision>
    <origin xyz="-0.089801 -0.2134 -0.010493" rpy="0 0 0"/>
    <geometry>
      <mesh filename="package://quadru_description/meshes/bl_lower_1.stl" scale="0.001 0.001 0.001"/>
    </geometry>
  </collision>
</link>

<link name="fr_shoulder_1">
  <inertial>
    <origin xyz="-0.020383660429034736 -0.016149105311451188 0.007595735398294163" rpy="0 0 0"/>
    <mass value="0.08997986177136641"/>
    <inertia ixx="3.8e-05" iyy="0.000111" izz="8.9e-05" ixy="0.0" iyz="-0.0" ixz="2.4e-05"/>
  </inertial>
  <visual>
    <origin xyz="0.0767 0.0406 -6e-06" rpy="0 0 0"/>
    <geometry>
      <mesh filename="package://quadru_description/meshes/fr_shoulder_1.stl" scale="0.001 0.001 0.001"/>
    </geometry>
    <material name="silver"/>
  </visual>
  <collision>
    <origin xyz="0.0767 0.0406 -6e-06" rpy="0 0 0"/>
    <geometry>
      <mesh filename="package://quadru_description/meshes/fr_shoulder_1.stl" scale="0.001 0.001 0.001"/>
    </geometry>
  </collision>
</link>

<link name="fr_upper_1">
  <inertial>
    <origin xyz="-0.0287420385234486 -0.047056574856869676 0.003944651495702396" rpy="0 0 0"/>
    <mass value="0.06768345772988309"/>
    <inertia ixx="8.3e-05" iyy="4.8e-05" izz="0.000115" ixy="2e-06" iyz="-3e-06" ixz="0.0"/>
  </inertial>
  <visual>
    <origin xyz="0.104399 0.0566 -0.010508" rpy="0 0 0"/>
    <geometry>
      <mesh filename="package://quadru_description/meshes/fr_upper_1.stl" scale="0.001 0.001 0.001"/>
    </geometry>
    <material name="silver"/>
  </visual>
  <collision>
    <origin xyz="0.104399 0.0566 -0.010508" rpy="0 0 0"/>
    <geometry>
      <mesh filename="package://quadru_description/meshes/fr_upper_1.stl" scale="0.001 0.001 0.001"/>
    </geometry>
  </collision>
</link>

<link name="fr_lower_1">
  <inertial>
    <origin xyz="0.02588563542684455 0.03867162578196459 0.0007177686909025493" rpy="0 0 0"/>
    <mass value="0.08196110083089321"/>
    <inertia ixx="0.000138" iyy="1.7e-05" izz="0.000148" ixy="-8e-06" iyz="2e-06" ixz="-0.0"/>
  </inertial>
  <visual>
    <origin xyz="0.155999 0.1566 -0.010511" rpy="0 0 0"/>
    <geometry>
      <mesh filename="package://quadru_description/meshes/fr_lower_1.stl" scale="0.001 0.001 0.001"/>
    </geometry>
    <material name="silver"/>
  </visual>
  <collision>
    <origin xyz="0.155999 0.1566 -0.010511" rpy="0 0 0"/>
    <geometry>
      <mesh filename="package://quadru_description/meshes/fr_lower_1.stl" scale="0.001 0.001 0.001"/>
    </geometry>
  </collision>
</link>

<joint name="fl1" type="continuous">
  <origin xyz="0.0105 -0.0406 -1e-06" rpy="0 0 0"/>
  <parent link="base_link"/>
  <child link="fl_shoulder_1"/>
  <axis xyz="-0.0 -1.0 -0.0"/>
</joint>

<joint name="fl2" type="continuous">
  <origin xyz="0.027701 -0.016 0.010498" rpy="0 0 0"/>
  <parent link="fl_shoulder_1"/>
  <child link="fl_upper_1"/>
  <axis xyz="1.0 -0.0 -7.2e-05"/>
</joint>

<joint name="fl3" type="continuous">
  <origin xyz="0.0516 -0.1 -4e-06" rpy="0 0 0"/>
  <parent link="fl_upper_1"/>
  <child link="fl_lower_1"/>
  <axis xyz="-1.0 0.0 7.2e-05"/>
</joint>

<joint name="bl1" type="continuous">
  <origin xyz="0.0105 0.0974 -1e-06" rpy="0 0 0"/>
  <parent link="base_link"/>
  <child link="bl_shoulder_1"/>
  <axis xyz="0.0 1.0 0.0"/>
</joint>

<joint name="bl2" type="continuous">
  <origin xyz="0.027701 0.016 0.010498" rpy="0 0 0"/>
  <parent link="bl_shoulder_1"/>
  <child link="bl_upper_1"/>
  <axis xyz="1.0 -0.0 -7.2e-05"/>
</joint>

<joint name="br1" type="continuous">
  <origin xyz="-0.0767 0.0974 6e-06" rpy="0 0 0"/>
  <parent link="base_link"/>
  <child link="br_shoulder_1"/>
  <axis xyz="0.0 1.0 0.0"/>
</joint>

<joint name="br2" type="continuous">
  <origin xyz="-0.027699 0.016 0.010502" rpy="0 0 0"/>
  <parent link="br_shoulder_1"/>
  <child link="br_upper_1"/>
  <axis xyz="-1.0 0.0 7.2e-05"/>
</joint>

<joint name="br3" type="continuous">
  <origin xyz="-0.0516 0.1 3e-06" rpy="0 0 0"/>
  <parent link="br_upper_1"/>
  <child link="br_lower_1"/>
  <axis xyz="1.0 -0.0 -7.2e-05"/>
</joint>

<joint name="bl3" type="continuous">
  <origin xyz="0.0516 0.1 -4e-06" rpy="0 0 0"/>
  <parent link="bl_upper_1"/>
  <child link="bl_lower_1"/>
  <axis xyz="-1.0 -0.0 7.2e-05"/>
</joint>

<joint name="fr1" type="continuous">
  <origin xyz="-0.0767 -0.0406 6e-06" rpy="0 0 0"/>
  <parent link="base_link"/>
  <child link="fr_shoulder_1"/>
  <axis xyz="-0.0 -1.0 -0.0"/>
</joint>

<joint name="fr2" type="continuous">
  <origin xyz="-0.027699 -0.016 0.010502" rpy="0 0 0"/>
  <parent link="fr_shoulder_1"/>
  <child link="fr_upper_1"/>
  <axis xyz="-1.0 0.0 7.2e-05"/>
</joint>

<joint name="fr3" type="continuous">
  <origin xyz="-0.0516 -0.1 3e-06" rpy="0 0 0"/>
  <parent link="fr_upper_1"/>
  <child link="fr_lower_1"/>
  <axis xyz="1.0 0.0 -7.2e-05"/>
</joint>

</robot>
